2024-05-11 10:48:59,566 FILE: creds.py IN: create_new_token MESSAGE: Ошибка получения iam_token: HTTPConnectionPool(host='169.254.169.254', port=80): Max retries exceeded with url: /computeMetadata/v1/instance/service-accounts/default/token (Caused by NewConnectionError('<urllib3.connection.HTTPConnection object at 0x000001D9CEFEE920>: Failed to establish a new connection: [WinError 10051] Сделана попытка выполнить операцию на сокете при отключенной сети'))
2024-05-11 10:49:00,078 FILE: creds.py IN: create_new_token MESSAGE: Ошибка получения iam_token: HTTPConnectionPool(host='169.254.169.254', port=80): Max retries exceeded with url: /computeMetadata/v1/instance/service-accounts/default/token (Caused by NewConnectionError('<urllib3.connection.HTTPConnection object at 0x000001D9CF051270>: Failed to establish a new connection: [WinError 10051] Сделана попытка выполнить операцию на сокете при отключенной сети'))
2024-05-11 10:49:00,197 FILE: creds.py IN: create_new_token MESSAGE: Ошибка получения iam_token: HTTPConnectionPool(host='169.254.169.254', port=80): Max retries exceeded with url: /computeMetadata/v1/instance/service-accounts/default/token (Caused by NewConnectionError('<urllib3.connection.HTTPConnection object at 0x000001D9CF0514B0>: Failed to establish a new connection: [WinError 10051] Сделана попытка выполнить операцию на сокете при отключенной сети'))
2024-05-11 10:49:00,198 FILE: creds.py IN: create_new_token MESSAGE: Ошибка получения iam_token: HTTPConnectionPool(host='169.254.169.254', port=80): Max retries exceeded with url: /computeMetadata/v1/instance/service-accounts/default/token (Caused by NewConnectionError('<urllib3.connection.HTTPConnection object at 0x000001D9CF052680>: Failed to establish a new connection: [WinError 10051] Сделана попытка выполнить операцию на сокете при отключенной сети'))
2024-05-11 10:49:00,199 FILE: creds.py IN: create_new_token MESSAGE: Ошибка получения iam_token: HTTPConnectionPool(host='169.254.169.254', port=80): Max retries exceeded with url: /computeMetadata/v1/instance/service-accounts/default/token (Caused by NewConnectionError('<urllib3.connection.HTTPConnection object at 0x000001D9CF052470>: Failed to establish a new connection: [WinError 10051] Сделана попытка выполнить операцию на сокете при отключенной сети'))
2024-05-11 10:49:00,877 FILE: creds.py IN: create_new_token MESSAGE: Ошибка получения iam_token: HTTPConnectionPool(host='169.254.169.254', port=80): Max retries exceeded with url: /computeMetadata/v1/instance/service-accounts/default/token (Caused by NewConnectionError('<urllib3.connection.HTTPConnection object at 0x000001D9CF051240>: Failed to establish a new connection: [WinError 10051] Сделана попытка выполнить операцию на сокете при отключенной сети'))
2024-05-11 10:49:00,878 FILE: creds.py IN: create_new_token MESSAGE: Ошибка получения iam_token: HTTPConnectionPool(host='169.254.169.254', port=80): Max retries exceeded with url: /computeMetadata/v1/instance/service-accounts/default/token (Caused by NewConnectionError('<urllib3.connection.HTTPConnection object at 0x000001D9CF052E00>: Failed to establish a new connection: [WinError 10051] Сделана попытка выполнить операцию на сокете при отключенной сети'))
2024-05-11 10:49:07,879 FILE: creds.py IN: create_new_token MESSAGE: Ошибка получения iam_token: HTTPConnectionPool(host='169.254.169.254', port=80): Max retries exceeded with url: /computeMetadata/v1/instance/service-accounts/default/token (Caused by NewConnectionError('<urllib3.connection.HTTPConnection object at 0x000001D9CF051C90>: Failed to establish a new connection: [WinError 10051] Сделана попытка выполнить операцию на сокете при отключенной сети'))
2024-05-11 10:49:08,000 FILE: creds.py IN: create_new_token MESSAGE: Ошибка получения iam_token: HTTPConnectionPool(host='169.254.169.254', port=80): Max retries exceeded with url: /computeMetadata/v1/instance/service-accounts/default/token (Caused by NewConnectionError('<urllib3.connection.HTTPConnection object at 0x000001D9CF051480>: Failed to establish a new connection: [WinError 10051] Сделана попытка выполнить операцию на сокете при отключенной сети'))
2024-05-11 10:49:08,119 FILE: creds.py IN: create_new_token MESSAGE: Ошибка получения iam_token: HTTPConnectionPool(host='169.254.169.254', port=80): Max retries exceeded with url: /computeMetadata/v1/instance/service-accounts/default/token (Caused by NewConnectionError('<urllib3.connection.HTTPConnection object at 0x000001D9CF050BE0>: Failed to establish a new connection: [WinError 10051] Сделана попытка выполнить операцию на сокете при отключенной сети'))
2024-05-11 10:49:08,120 FILE: creds.py IN: create_new_token MESSAGE: Ошибка получения iam_token: HTTPConnectionPool(host='169.254.169.254', port=80): Max retries exceeded with url: /computeMetadata/v1/instance/service-accounts/default/token (Caused by NewConnectionError('<urllib3.connection.HTTPConnection object at 0x000001D9CF0522F0>: Failed to establish a new connection: [WinError 10051] Сделана попытка выполнить операцию на сокете при отключенной сети'))
2024-05-11 10:49:08,121 FILE: creds.py IN: create_new_token MESSAGE: Ошибка получения iam_token: HTTPConnectionPool(host='169.254.169.254', port=80): Max retries exceeded with url: /computeMetadata/v1/instance/service-accounts/default/token (Caused by NewConnectionError('<urllib3.connection.HTTPConnection object at 0x000001D9CF07C250>: Failed to establish a new connection: [WinError 10051] Сделана попытка выполнить операцию на сокете при отключенной сети'))
2024-05-11 10:49:08,948 FILE: creds.py IN: create_new_token MESSAGE: Ошибка получения iam_token: HTTPConnectionPool(host='169.254.169.254', port=80): Max retries exceeded with url: /computeMetadata/v1/instance/service-accounts/default/token (Caused by NewConnectionError('<urllib3.connection.HTTPConnection object at 0x000001D9CF0528C0>: Failed to establish a new connection: [WinError 10051] Сделана попытка выполнить операцию на сокете при отключенной сети'))
2024-05-11 10:49:08,949 FILE: creds.py IN: create_new_token MESSAGE: Ошибка получения iam_token: HTTPConnectionPool(host='169.254.169.254', port=80): Max retries exceeded with url: /computeMetadata/v1/instance/service-accounts/default/token (Caused by NewConnectionError('<urllib3.connection.HTTPConnection object at 0x000001D9CF0518A0>: Failed to establish a new connection: [WinError 10051] Сделана попытка выполнить операцию на сокете при отключенной сети'))
